[2024-08-29T17:00:33.862+0000] {local_task_job_runner.py:123} INFO - ::group::Pre task execution logs
[2024-08-29T17:00:33.870+0000] {taskinstance.py:2603} INFO - Dependencies all met for dep_context=non-requeueable deps ti=<TaskInstance: zillow_analytics_dag.tsk_is_file_in_s3_available manual__2024-08-29T17:00:24.282349+00:00 [queued]>
[2024-08-29T17:00:33.875+0000] {taskinstance.py:2603} INFO - Dependencies all met for dep_context=requeueable deps ti=<TaskInstance: zillow_analytics_dag.tsk_is_file_in_s3_available manual__2024-08-29T17:00:24.282349+00:00 [queued]>
[2024-08-29T17:00:33.875+0000] {taskinstance.py:2856} INFO - Starting attempt 1 of 3
[2024-08-29T17:00:33.892+0000] {taskinstance.py:2879} INFO - Executing <Task(S3KeySensor): tsk_is_file_in_s3_available> on 2024-08-29 17:00:24.282349+00:00
[2024-08-29T17:00:33.895+0000] {standard_task_runner.py:72} INFO - Started process 28482 to run task
[2024-08-29T17:00:33.898+0000] {standard_task_runner.py:104} INFO - Running: ['airflow', 'tasks', 'run', 'zillow_analytics_dag', 'tsk_is_file_in_s3_available', 'manual__2024-08-29T17:00:24.282349+00:00', '--job-id', '58', '--raw', '--subdir', 'DAGS_FOLDER/zillow_analytics.py', '--cfg-path', '/tmp/tmpo1q8rxl7']
[2024-08-29T17:00:33.899+0000] {standard_task_runner.py:105} INFO - Job 58: Subtask tsk_is_file_in_s3_available
[2024-08-29T17:00:33.932+0000] {task_command.py:467} INFO - Running <TaskInstance: zillow_analytics_dag.tsk_is_file_in_s3_available manual__2024-08-29T17:00:24.282349+00:00 [running]> on host ip-172-31-11-44.eu-west-3.compute.internal
[2024-08-29T17:00:33.996+0000] {taskinstance.py:3122} INFO - Exporting env vars: AIRFLOW_CTX_DAG_EMAIL='says@master.com' AIRFLOW_CTX_DAG_OWNER='airflow' AIRFLOW_CTX_DAG_ID='zillow_analytics_dag' AIRFLOW_CTX_TASK_ID='tsk_is_file_in_s3_available' AIRFLOW_CTX_EXECUTION_DATE='2024-08-29T17:00:24.282349+00:00' AIRFLOW_CTX_TRY_NUMBER='1' AIRFLOW_CTX_DAG_RUN_ID='manual__2024-08-29T17:00:24.282349+00:00'
[2024-08-29T17:00:33.996+0000] {taskinstance.py:731} INFO - ::endgroup::
[2024-08-29T17:00:34.008+0000] {baseoperator.py:405} WARNING - S3KeySensor.execute cannot be called outside TaskInstance!
[2024-08-29T17:00:34.008+0000] {s3.py:118} INFO - Poking for key : s3://cleaned-endtoend-csv-bucket/resonse_data_29082024170027.csv
[2024-08-29T17:00:34.013+0000] {base.py:84} INFO - Retrieving connection 'aws_s3_conn'
[2024-08-29T17:00:34.013+0000] {connection_wrapper.py:388} INFO - AWS Connection (conn_id='aws_s3_conn', conn_type='aws') credentials retrieved from login and password.
[2024-08-29T17:00:39.359+0000] {s3.py:118} INFO - Poking for key : s3://cleaned-endtoend-csv-bucket/resonse_data_29082024170027.csv
[2024-08-29T17:00:44.368+0000] {s3.py:118} INFO - Poking for key : s3://cleaned-endtoend-csv-bucket/resonse_data_29082024170027.csv
[2024-08-29T17:00:49.377+0000] {s3.py:118} INFO - Poking for key : s3://cleaned-endtoend-csv-bucket/resonse_data_29082024170027.csv
[2024-08-29T17:00:54.388+0000] {s3.py:118} INFO - Poking for key : s3://cleaned-endtoend-csv-bucket/resonse_data_29082024170027.csv
[2024-08-29T17:00:59.398+0000] {s3.py:118} INFO - Poking for key : s3://cleaned-endtoend-csv-bucket/resonse_data_29082024170027.csv
[2024-08-29T17:01:04.406+0000] {s3.py:118} INFO - Poking for key : s3://cleaned-endtoend-csv-bucket/resonse_data_29082024170027.csv
[2024-08-29T17:01:09.417+0000] {s3.py:118} INFO - Poking for key : s3://cleaned-endtoend-csv-bucket/resonse_data_29082024170027.csv
[2024-08-29T17:01:14.428+0000] {s3.py:118} INFO - Poking for key : s3://cleaned-endtoend-csv-bucket/resonse_data_29082024170027.csv
[2024-08-29T17:01:19.439+0000] {s3.py:118} INFO - Poking for key : s3://cleaned-endtoend-csv-bucket/resonse_data_29082024170027.csv
[2024-08-29T17:01:24.451+0000] {s3.py:118} INFO - Poking for key : s3://cleaned-endtoend-csv-bucket/resonse_data_29082024170027.csv
[2024-08-29T17:01:29.461+0000] {s3.py:118} INFO - Poking for key : s3://cleaned-endtoend-csv-bucket/resonse_data_29082024170027.csv
[2024-08-29T17:01:34.470+0000] {s3.py:118} INFO - Poking for key : s3://cleaned-endtoend-csv-bucket/resonse_data_29082024170027.csv
[2024-08-29T17:01:34.479+0000] {taskinstance.py:3301} ERROR - Task failed with exception
Traceback (most recent call last):
  File "/home/ubuntu/myenv/lib/python3.12/site-packages/airflow/models/taskinstance.py", line 767, in _execute_task
    result = _execute_callable(context=context, **execute_callable_kwargs)
             ^^^^^^^^^^^^^^^^^^^^^^^^^^^^^^^^^^^^^^^^^^^^^^^^^^^^^^^^^^^^^
  File "/home/ubuntu/myenv/lib/python3.12/site-packages/airflow/models/taskinstance.py", line 733, in _execute_callable
    return ExecutionCallableRunner(
           ^^^^^^^^^^^^^^^^^^^^^^^^
  File "/home/ubuntu/myenv/lib/python3.12/site-packages/airflow/utils/operator_helpers.py", line 252, in run
    return self.func(*args, **kwargs)
           ^^^^^^^^^^^^^^^^^^^^^^^^^^
  File "/home/ubuntu/myenv/lib/python3.12/site-packages/airflow/models/baseoperator.py", line 406, in wrapper
    return func(self, *args, **kwargs)
           ^^^^^^^^^^^^^^^^^^^^^^^^^^^
  File "/home/ubuntu/myenv/lib/python3.12/site-packages/airflow/providers/amazon/aws/sensors/s3.py", line 189, in execute
    super().execute(context)
  File "/home/ubuntu/myenv/lib/python3.12/site-packages/airflow/models/baseoperator.py", line 406, in wrapper
    return func(self, *args, **kwargs)
           ^^^^^^^^^^^^^^^^^^^^^^^^^^^
  File "/home/ubuntu/myenv/lib/python3.12/site-packages/airflow/sensors/base.py", line 323, in execute
    raise AirflowSensorTimeout(message)
airflow.exceptions.AirflowSensorTimeout: Sensor has timed out; run duration of 60.470667935000165 seconds exceeds the specified timeout of 60.0.
[2024-08-29T17:01:34.482+0000] {taskinstance.py:1225} INFO - Immediate failure requested. Marking task as FAILED. dag_id=zillow_analytics_dag, task_id=tsk_is_file_in_s3_available, run_id=manual__2024-08-29T17:00:24.282349+00:00, execution_date=20240829T170024, start_date=20240829T170033, end_date=20240829T170134
[2024-08-29T17:01:34.495+0000] {taskinstance.py:340} INFO - ::group::Post task execution logs
[2024-08-29T17:01:34.495+0000] {standard_task_runner.py:124} ERROR - Failed to execute job 58 for task tsk_is_file_in_s3_available (Sensor has timed out; run duration of 60.470667935000165 seconds exceeds the specified timeout of 60.0.; 28482)
Traceback (most recent call last):
  File "/home/ubuntu/myenv/lib/python3.12/site-packages/airflow/task/task_runner/standard_task_runner.py", line 117, in _start_by_fork
    ret = args.func(args, dag=self.dag)
          ^^^^^^^^^^^^^^^^^^^^^^^^^^^^^
  File "/home/ubuntu/myenv/lib/python3.12/site-packages/airflow/cli/cli_config.py", line 49, in command
    return func(*args, **kwargs)
           ^^^^^^^^^^^^^^^^^^^^^
  File "/home/ubuntu/myenv/lib/python3.12/site-packages/airflow/utils/cli.py", line 115, in wrapper
    return f(*args, **kwargs)
           ^^^^^^^^^^^^^^^^^^
  File "/home/ubuntu/myenv/lib/python3.12/site-packages/airflow/cli/commands/task_command.py", line 483, in task_run
    task_return_code = _run_task_by_selected_method(args, _dag, ti)
                       ^^^^^^^^^^^^^^^^^^^^^^^^^^^^^^^^^^^^^^^^^^^^
  File "/home/ubuntu/myenv/lib/python3.12/site-packages/airflow/cli/commands/task_command.py", line 256, in _run_task_by_selected_method
    return _run_raw_task(args, ti)
           ^^^^^^^^^^^^^^^^^^^^^^^
  File "/home/ubuntu/myenv/lib/python3.12/site-packages/airflow/cli/commands/task_command.py", line 341, in _run_raw_task
    return ti._run_raw_task(
           ^^^^^^^^^^^^^^^^^
  File "/home/ubuntu/myenv/lib/python3.12/site-packages/airflow/utils/session.py", line 97, in wrapper
    return func(*args, session=session, **kwargs)
           ^^^^^^^^^^^^^^^^^^^^^^^^^^^^^^^^^^^^^^
  File "/home/ubuntu/myenv/lib/python3.12/site-packages/airflow/models/taskinstance.py", line 2995, in _run_raw_task
    return _run_raw_task(
           ^^^^^^^^^^^^^^
  File "/home/ubuntu/myenv/lib/python3.12/site-packages/airflow/models/taskinstance.py", line 273, in _run_raw_task
    TaskInstance._execute_task_with_callbacks(
  File "/home/ubuntu/myenv/lib/python3.12/site-packages/airflow/models/taskinstance.py", line 3149, in _execute_task_with_callbacks
    result = self._execute_task(context, task_orig)
             ^^^^^^^^^^^^^^^^^^^^^^^^^^^^^^^^^^^^^^
  File "/home/ubuntu/myenv/lib/python3.12/site-packages/airflow/models/taskinstance.py", line 3173, in _execute_task
    return _execute_task(self, context, task_orig)
           ^^^^^^^^^^^^^^^^^^^^^^^^^^^^^^^^^^^^^^^
  File "/home/ubuntu/myenv/lib/python3.12/site-packages/airflow/models/taskinstance.py", line 767, in _execute_task
    result = _execute_callable(context=context, **execute_callable_kwargs)
             ^^^^^^^^^^^^^^^^^^^^^^^^^^^^^^^^^^^^^^^^^^^^^^^^^^^^^^^^^^^^^
  File "/home/ubuntu/myenv/lib/python3.12/site-packages/airflow/models/taskinstance.py", line 733, in _execute_callable
    return ExecutionCallableRunner(
           ^^^^^^^^^^^^^^^^^^^^^^^^
  File "/home/ubuntu/myenv/lib/python3.12/site-packages/airflow/utils/operator_helpers.py", line 252, in run
    return self.func(*args, **kwargs)
           ^^^^^^^^^^^^^^^^^^^^^^^^^^
  File "/home/ubuntu/myenv/lib/python3.12/site-packages/airflow/models/baseoperator.py", line 406, in wrapper
    return func(self, *args, **kwargs)
           ^^^^^^^^^^^^^^^^^^^^^^^^^^^
  File "/home/ubuntu/myenv/lib/python3.12/site-packages/airflow/providers/amazon/aws/sensors/s3.py", line 189, in execute
    super().execute(context)
  File "/home/ubuntu/myenv/lib/python3.12/site-packages/airflow/models/baseoperator.py", line 406, in wrapper
    return func(self, *args, **kwargs)
           ^^^^^^^^^^^^^^^^^^^^^^^^^^^
  File "/home/ubuntu/myenv/lib/python3.12/site-packages/airflow/sensors/base.py", line 323, in execute
    raise AirflowSensorTimeout(message)
airflow.exceptions.AirflowSensorTimeout: Sensor has timed out; run duration of 60.470667935000165 seconds exceeds the specified timeout of 60.0.
[2024-08-29T17:01:34.521+0000] {local_task_job_runner.py:261} INFO - Task exited with return code 1
[2024-08-29T17:01:34.529+0000] {taskinstance.py:3891} INFO - 0 downstream tasks scheduled from follow-on schedule check
[2024-08-29T17:01:34.530+0000] {local_task_job_runner.py:240} INFO - ::endgroup::
