[2024-08-29T16:49:36.431+0000] {local_task_job_runner.py:123} INFO - ::group::Pre task execution logs
[2024-08-29T16:49:36.439+0000] {taskinstance.py:2603} INFO - Dependencies all met for dep_context=non-requeueable deps ti=<TaskInstance: zillow_analytics_dag.tsk_is_file_in_s3_available manual__2024-08-29T16:49:28.121314+00:00 [queued]>
[2024-08-29T16:49:36.444+0000] {taskinstance.py:2603} INFO - Dependencies all met for dep_context=requeueable deps ti=<TaskInstance: zillow_analytics_dag.tsk_is_file_in_s3_available manual__2024-08-29T16:49:28.121314+00:00 [queued]>
[2024-08-29T16:49:36.444+0000] {taskinstance.py:2856} INFO - Starting attempt 1 of 3
[2024-08-29T16:49:36.461+0000] {taskinstance.py:2879} INFO - Executing <Task(S3KeySensor): tsk_is_file_in_s3_available> on 2024-08-29 16:49:28.121314+00:00
[2024-08-29T16:49:36.464+0000] {standard_task_runner.py:72} INFO - Started process 13029 to run task
[2024-08-29T16:49:36.467+0000] {standard_task_runner.py:104} INFO - Running: ['airflow', 'tasks', 'run', 'zillow_analytics_dag', 'tsk_is_file_in_s3_available', 'manual__2024-08-29T16:49:28.121314+00:00', '--job-id', '47', '--raw', '--subdir', 'DAGS_FOLDER/zillow_analytics.py', '--cfg-path', '/tmp/tmp04gcvipi']
[2024-08-29T16:49:36.469+0000] {standard_task_runner.py:105} INFO - Job 47: Subtask tsk_is_file_in_s3_available
[2024-08-29T16:49:36.506+0000] {task_command.py:467} INFO - Running <TaskInstance: zillow_analytics_dag.tsk_is_file_in_s3_available manual__2024-08-29T16:49:28.121314+00:00 [running]> on host ip-172-31-11-44.eu-west-3.compute.internal
[2024-08-29T16:49:36.572+0000] {taskinstance.py:3122} INFO - Exporting env vars: AIRFLOW_CTX_DAG_EMAIL='says@master.com' AIRFLOW_CTX_DAG_OWNER='airflow' AIRFLOW_CTX_DAG_ID='zillow_analytics_dag' AIRFLOW_CTX_TASK_ID='tsk_is_file_in_s3_available' AIRFLOW_CTX_EXECUTION_DATE='2024-08-29T16:49:28.121314+00:00' AIRFLOW_CTX_TRY_NUMBER='1' AIRFLOW_CTX_DAG_RUN_ID='manual__2024-08-29T16:49:28.121314+00:00'
[2024-08-29T16:49:36.573+0000] {taskinstance.py:731} INFO - ::endgroup::
[2024-08-29T16:49:36.585+0000] {baseoperator.py:405} WARNING - S3KeySensor.execute cannot be called outside TaskInstance!
[2024-08-29T16:49:36.585+0000] {s3.py:118} INFO - Poking for key : s3://cleaned-endtoend-csv-bucket/resonse_data_29082024164930.csv
[2024-08-29T16:49:36.589+0000] {base.py:84} INFO - Retrieving connection 'aws_s3_conn'
[2024-08-29T16:49:36.590+0000] {connection_wrapper.py:388} INFO - AWS Connection (conn_id='aws_s3_conn', conn_type='aws') credentials retrieved from login and password.
[2024-08-29T16:49:41.933+0000] {s3.py:118} INFO - Poking for key : s3://cleaned-endtoend-csv-bucket/resonse_data_29082024164930.csv
[2024-08-29T16:49:46.943+0000] {s3.py:118} INFO - Poking for key : s3://cleaned-endtoend-csv-bucket/resonse_data_29082024164930.csv
[2024-08-29T16:49:51.952+0000] {s3.py:118} INFO - Poking for key : s3://cleaned-endtoend-csv-bucket/resonse_data_29082024164930.csv
[2024-08-29T16:49:56.964+0000] {s3.py:118} INFO - Poking for key : s3://cleaned-endtoend-csv-bucket/resonse_data_29082024164930.csv
[2024-08-29T16:50:01.977+0000] {s3.py:118} INFO - Poking for key : s3://cleaned-endtoend-csv-bucket/resonse_data_29082024164930.csv
[2024-08-29T16:50:07.027+0000] {s3.py:118} INFO - Poking for key : s3://cleaned-endtoend-csv-bucket/resonse_data_29082024164930.csv
[2024-08-29T16:50:12.041+0000] {s3.py:118} INFO - Poking for key : s3://cleaned-endtoend-csv-bucket/resonse_data_29082024164930.csv
[2024-08-29T16:50:17.053+0000] {s3.py:118} INFO - Poking for key : s3://cleaned-endtoend-csv-bucket/resonse_data_29082024164930.csv
[2024-08-29T16:50:22.067+0000] {s3.py:118} INFO - Poking for key : s3://cleaned-endtoend-csv-bucket/resonse_data_29082024164930.csv
[2024-08-29T16:50:27.086+0000] {s3.py:118} INFO - Poking for key : s3://cleaned-endtoend-csv-bucket/resonse_data_29082024164930.csv
[2024-08-29T16:50:32.095+0000] {s3.py:118} INFO - Poking for key : s3://cleaned-endtoend-csv-bucket/resonse_data_29082024164930.csv
[2024-08-29T16:50:37.112+0000] {s3.py:118} INFO - Poking for key : s3://cleaned-endtoend-csv-bucket/resonse_data_29082024164930.csv
[2024-08-29T16:50:37.125+0000] {taskinstance.py:3301} ERROR - Task failed with exception
Traceback (most recent call last):
  File "/home/ubuntu/myenv/lib/python3.12/site-packages/airflow/models/taskinstance.py", line 767, in _execute_task
    result = _execute_callable(context=context, **execute_callable_kwargs)
             ^^^^^^^^^^^^^^^^^^^^^^^^^^^^^^^^^^^^^^^^^^^^^^^^^^^^^^^^^^^^^
  File "/home/ubuntu/myenv/lib/python3.12/site-packages/airflow/models/taskinstance.py", line 733, in _execute_callable
    return ExecutionCallableRunner(
           ^^^^^^^^^^^^^^^^^^^^^^^^
  File "/home/ubuntu/myenv/lib/python3.12/site-packages/airflow/utils/operator_helpers.py", line 252, in run
    return self.func(*args, **kwargs)
           ^^^^^^^^^^^^^^^^^^^^^^^^^^
  File "/home/ubuntu/myenv/lib/python3.12/site-packages/airflow/models/baseoperator.py", line 406, in wrapper
    return func(self, *args, **kwargs)
           ^^^^^^^^^^^^^^^^^^^^^^^^^^^
  File "/home/ubuntu/myenv/lib/python3.12/site-packages/airflow/providers/amazon/aws/sensors/s3.py", line 189, in execute
    super().execute(context)
  File "/home/ubuntu/myenv/lib/python3.12/site-packages/airflow/models/baseoperator.py", line 406, in wrapper
    return func(self, *args, **kwargs)
           ^^^^^^^^^^^^^^^^^^^^^^^^^^^
  File "/home/ubuntu/myenv/lib/python3.12/site-packages/airflow/sensors/base.py", line 323, in execute
    raise AirflowSensorTimeout(message)
airflow.exceptions.AirflowSensorTimeout: Sensor has timed out; run duration of 60.53976797600035 seconds exceeds the specified timeout of 60.0.
[2024-08-29T16:50:37.128+0000] {taskinstance.py:1225} INFO - Immediate failure requested. Marking task as FAILED. dag_id=zillow_analytics_dag, task_id=tsk_is_file_in_s3_available, run_id=manual__2024-08-29T16:49:28.121314+00:00, execution_date=20240829T164928, start_date=20240829T164936, end_date=20240829T165037
[2024-08-29T16:50:37.142+0000] {taskinstance.py:340} INFO - ::group::Post task execution logs
[2024-08-29T16:50:37.143+0000] {standard_task_runner.py:124} ERROR - Failed to execute job 47 for task tsk_is_file_in_s3_available (Sensor has timed out; run duration of 60.53976797600035 seconds exceeds the specified timeout of 60.0.; 13029)
Traceback (most recent call last):
  File "/home/ubuntu/myenv/lib/python3.12/site-packages/airflow/task/task_runner/standard_task_runner.py", line 117, in _start_by_fork
    ret = args.func(args, dag=self.dag)
          ^^^^^^^^^^^^^^^^^^^^^^^^^^^^^
  File "/home/ubuntu/myenv/lib/python3.12/site-packages/airflow/cli/cli_config.py", line 49, in command
    return func(*args, **kwargs)
           ^^^^^^^^^^^^^^^^^^^^^
  File "/home/ubuntu/myenv/lib/python3.12/site-packages/airflow/utils/cli.py", line 115, in wrapper
    return f(*args, **kwargs)
           ^^^^^^^^^^^^^^^^^^
  File "/home/ubuntu/myenv/lib/python3.12/site-packages/airflow/cli/commands/task_command.py", line 483, in task_run
    task_return_code = _run_task_by_selected_method(args, _dag, ti)
                       ^^^^^^^^^^^^^^^^^^^^^^^^^^^^^^^^^^^^^^^^^^^^
  File "/home/ubuntu/myenv/lib/python3.12/site-packages/airflow/cli/commands/task_command.py", line 256, in _run_task_by_selected_method
    return _run_raw_task(args, ti)
           ^^^^^^^^^^^^^^^^^^^^^^^
  File "/home/ubuntu/myenv/lib/python3.12/site-packages/airflow/cli/commands/task_command.py", line 341, in _run_raw_task
    return ti._run_raw_task(
           ^^^^^^^^^^^^^^^^^
  File "/home/ubuntu/myenv/lib/python3.12/site-packages/airflow/utils/session.py", line 97, in wrapper
    return func(*args, session=session, **kwargs)
           ^^^^^^^^^^^^^^^^^^^^^^^^^^^^^^^^^^^^^^
  File "/home/ubuntu/myenv/lib/python3.12/site-packages/airflow/models/taskinstance.py", line 2995, in _run_raw_task
    return _run_raw_task(
           ^^^^^^^^^^^^^^
  File "/home/ubuntu/myenv/lib/python3.12/site-packages/airflow/models/taskinstance.py", line 273, in _run_raw_task
    TaskInstance._execute_task_with_callbacks(
  File "/home/ubuntu/myenv/lib/python3.12/site-packages/airflow/models/taskinstance.py", line 3149, in _execute_task_with_callbacks
    result = self._execute_task(context, task_orig)
             ^^^^^^^^^^^^^^^^^^^^^^^^^^^^^^^^^^^^^^
  File "/home/ubuntu/myenv/lib/python3.12/site-packages/airflow/models/taskinstance.py", line 3173, in _execute_task
    return _execute_task(self, context, task_orig)
           ^^^^^^^^^^^^^^^^^^^^^^^^^^^^^^^^^^^^^^^
  File "/home/ubuntu/myenv/lib/python3.12/site-packages/airflow/models/taskinstance.py", line 767, in _execute_task
    result = _execute_callable(context=context, **execute_callable_kwargs)
             ^^^^^^^^^^^^^^^^^^^^^^^^^^^^^^^^^^^^^^^^^^^^^^^^^^^^^^^^^^^^^
  File "/home/ubuntu/myenv/lib/python3.12/site-packages/airflow/models/taskinstance.py", line 733, in _execute_callable
    return ExecutionCallableRunner(
           ^^^^^^^^^^^^^^^^^^^^^^^^
  File "/home/ubuntu/myenv/lib/python3.12/site-packages/airflow/utils/operator_helpers.py", line 252, in run
    return self.func(*args, **kwargs)
           ^^^^^^^^^^^^^^^^^^^^^^^^^^
  File "/home/ubuntu/myenv/lib/python3.12/site-packages/airflow/models/baseoperator.py", line 406, in wrapper
    return func(self, *args, **kwargs)
           ^^^^^^^^^^^^^^^^^^^^^^^^^^^
  File "/home/ubuntu/myenv/lib/python3.12/site-packages/airflow/providers/amazon/aws/sensors/s3.py", line 189, in execute
    super().execute(context)
  File "/home/ubuntu/myenv/lib/python3.12/site-packages/airflow/models/baseoperator.py", line 406, in wrapper
    return func(self, *args, **kwargs)
           ^^^^^^^^^^^^^^^^^^^^^^^^^^^
  File "/home/ubuntu/myenv/lib/python3.12/site-packages/airflow/sensors/base.py", line 323, in execute
    raise AirflowSensorTimeout(message)
airflow.exceptions.AirflowSensorTimeout: Sensor has timed out; run duration of 60.53976797600035 seconds exceeds the specified timeout of 60.0.
[2024-08-29T16:50:37.159+0000] {local_task_job_runner.py:261} INFO - Task exited with return code 1
[2024-08-29T16:50:37.170+0000] {taskinstance.py:3891} INFO - 0 downstream tasks scheduled from follow-on schedule check
[2024-08-29T16:50:37.171+0000] {local_task_job_runner.py:240} INFO - ::endgroup::
