[2024-08-29T16:17:32.660+0000] {local_task_job_runner.py:123} INFO - ::group::Pre task execution logs
[2024-08-29T16:17:32.668+0000] {taskinstance.py:2603} INFO - Dependencies all met for dep_context=non-requeueable deps ti=<TaskInstance: zillow_analytics_dag.tsk_load_to_s3 scheduled__2024-08-28T00:00:00+00:00 [queued]>
[2024-08-29T16:17:32.673+0000] {taskinstance.py:2603} INFO - Dependencies all met for dep_context=requeueable deps ti=<TaskInstance: zillow_analytics_dag.tsk_load_to_s3 scheduled__2024-08-28T00:00:00+00:00 [queued]>
[2024-08-29T16:17:32.673+0000] {taskinstance.py:2856} INFO - Starting attempt 1 of 3
[2024-08-29T16:17:32.690+0000] {taskinstance.py:2879} INFO - Executing <Task(BashOperator): tsk_load_to_s3> on 2024-08-28 00:00:00+00:00
[2024-08-29T16:17:32.692+0000] {standard_task_runner.py:72} INFO - Started process 4600 to run task
[2024-08-29T16:17:32.695+0000] {standard_task_runner.py:104} INFO - Running: ['airflow', 'tasks', 'run', 'zillow_analytics_dag', 'tsk_load_to_s3', 'scheduled__2024-08-28T00:00:00+00:00', '--job-id', '25', '--raw', '--subdir', 'DAGS_FOLDER/zillow_analytics.py', '--cfg-path', '/tmp/tmpr09snp_l']
[2024-08-29T16:17:32.696+0000] {standard_task_runner.py:105} INFO - Job 25: Subtask tsk_load_to_s3
[2024-08-29T16:17:32.730+0000] {task_command.py:467} INFO - Running <TaskInstance: zillow_analytics_dag.tsk_load_to_s3 scheduled__2024-08-28T00:00:00+00:00 [running]> on host ip-172-31-11-44.eu-west-3.compute.internal
[2024-08-29T16:17:32.792+0000] {taskinstance.py:3122} INFO - Exporting env vars: AIRFLOW_CTX_DAG_EMAIL='says@master.com' AIRFLOW_CTX_DAG_OWNER='airflow' AIRFLOW_CTX_DAG_ID='zillow_analytics_dag' AIRFLOW_CTX_TASK_ID='tsk_load_to_s3' AIRFLOW_CTX_EXECUTION_DATE='2024-08-28T00:00:00+00:00' AIRFLOW_CTX_TRY_NUMBER='1' AIRFLOW_CTX_DAG_RUN_ID='scheduled__2024-08-28T00:00:00+00:00'
[2024-08-29T16:17:32.792+0000] {taskinstance.py:731} INFO - ::endgroup::
[2024-08-29T16:17:32.806+0000] {subprocess.py:63} INFO - Tmp dir root location: /tmp
[2024-08-29T16:17:32.806+0000] {subprocess.py:75} INFO - Running command: ['/usr/bin/bash', '-c', 'aws s3 mv /home/ubuntu/response_data_29082024161729.json s3://endtoend-bucket001/']
[2024-08-29T16:17:32.811+0000] {subprocess.py:86} INFO - Output:
[2024-08-29T16:17:33.068+0000] {local_task_job_runner.py:240} INFO - ::endgroup::
[2024-08-29T16:17:33.078+0000] {process_utils.py:132} INFO - Sending 15 to group 4600. PIDs of all processes in the group: [4602, 4600]
[2024-08-29T16:17:33.079+0000] {process_utils.py:87} INFO - Sending the signal 15 to group 4600
[2024-08-29T16:17:33.080+0000] {taskinstance.py:3083} ERROR - Received SIGTERM. Terminating subprocesses.
[2024-08-29T16:17:33.082+0000] {subprocess.py:104} INFO - Sending SIGTERM signal to process group
[2024-08-29T16:17:33.091+0000] {taskinstance.py:3301} ERROR - Task failed with exception
Traceback (most recent call last):
  File "/home/ubuntu/myenv/lib/python3.12/site-packages/airflow/models/taskinstance.py", line 767, in _execute_task
    result = _execute_callable(context=context, **execute_callable_kwargs)
             ^^^^^^^^^^^^^^^^^^^^^^^^^^^^^^^^^^^^^^^^^^^^^^^^^^^^^^^^^^^^^
  File "/home/ubuntu/myenv/lib/python3.12/site-packages/airflow/models/taskinstance.py", line 733, in _execute_callable
    return ExecutionCallableRunner(
           ^^^^^^^^^^^^^^^^^^^^^^^^
  File "/home/ubuntu/myenv/lib/python3.12/site-packages/airflow/utils/operator_helpers.py", line 252, in run
    return self.func(*args, **kwargs)
           ^^^^^^^^^^^^^^^^^^^^^^^^^^
  File "/home/ubuntu/myenv/lib/python3.12/site-packages/airflow/models/baseoperator.py", line 406, in wrapper
    return func(self, *args, **kwargs)
           ^^^^^^^^^^^^^^^^^^^^^^^^^^^
  File "/home/ubuntu/myenv/lib/python3.12/site-packages/airflow/operators/bash.py", line 240, in execute
    result = self.subprocess_hook.run_command(
             ^^^^^^^^^^^^^^^^^^^^^^^^^^^^^^^^^
  File "/home/ubuntu/myenv/lib/python3.12/site-packages/airflow/hooks/subprocess.py", line 91, in run_command
    for raw_line in iter(self.sub_process.stdout.readline, b""):
  File "/home/ubuntu/myenv/lib/python3.12/site-packages/airflow/models/taskinstance.py", line 3085, in signal_handler
    raise AirflowTaskTerminated("Task received SIGTERM signal")
airflow.exceptions.AirflowTaskTerminated: Task received SIGTERM signal
[2024-08-29T16:17:33.102+0000] {taskinstance.py:1225} INFO - Marking task as UP_FOR_RETRY. dag_id=zillow_analytics_dag, task_id=tsk_load_to_s3, run_id=scheduled__2024-08-28T00:00:00+00:00, execution_date=20240828T000000, start_date=20240829T161732, end_date=20240829T161733
[2024-08-29T16:17:33.117+0000] {taskinstance.py:340} INFO - ::group::Post task execution logs
[2024-08-29T16:17:33.134+0000] {process_utils.py:80} INFO - Process psutil.Process(pid=4600, status='terminated', exitcode=2, started='16:17:31') (4600) terminated with exit code 2
[2024-08-29T16:17:33.135+0000] {process_utils.py:80} INFO - Process psutil.Process(pid=4602, status='terminated', started='16:17:31') (4602) terminated with exit code None
[2024-08-29T16:17:36.653+0000] {local_task_job_runner.py:123} INFO - ::group::Pre task execution logs
[2024-08-29T16:17:36.659+0000] {taskinstance.py:2593} INFO - Dependencies not met for <TaskInstance: zillow_analytics_dag.tsk_load_to_s3 scheduled__2024-08-28T00:00:00+00:00 [up_for_retry]>, dependency 'Not In Retry Period' FAILED: Task is not ready for retry yet but will be retried automatically. Current date is 2024-08-29T16:17:36.659398+00:00 and task will be retried at 2024-08-29T16:17:48.102252+00:00.
[2024-08-29T16:17:36.663+0000] {local_task_job_runner.py:166} INFO - Task is not able to be run
