[2024-08-29T16:17:53.269+0000] {local_task_job_runner.py:123} INFO - ::group::Pre task execution logs
[2024-08-29T16:17:53.277+0000] {taskinstance.py:2603} INFO - Dependencies all met for dep_context=non-requeueable deps ti=<TaskInstance: zillow_analytics_dag.tsk_is_file_in_s3_available scheduled__2024-08-28T00:00:00+00:00 [queued]>
[2024-08-29T16:17:53.282+0000] {taskinstance.py:2603} INFO - Dependencies all met for dep_context=requeueable deps ti=<TaskInstance: zillow_analytics_dag.tsk_is_file_in_s3_available scheduled__2024-08-28T00:00:00+00:00 [queued]>
[2024-08-29T16:17:53.283+0000] {taskinstance.py:2856} INFO - Starting attempt 1 of 3
[2024-08-29T16:17:53.298+0000] {taskinstance.py:2879} INFO - Executing <Task(S3KeySensor): tsk_is_file_in_s3_available> on 2024-08-28 00:00:00+00:00
[2024-08-29T16:17:53.300+0000] {standard_task_runner.py:72} INFO - Started process 4867 to run task
[2024-08-29T16:17:53.303+0000] {standard_task_runner.py:104} INFO - Running: ['airflow', 'tasks', 'run', 'zillow_analytics_dag', 'tsk_is_file_in_s3_available', 'scheduled__2024-08-28T00:00:00+00:00', '--job-id', '30', '--raw', '--subdir', 'DAGS_FOLDER/zillow_analytics.py', '--cfg-path', '/tmp/tmpf2b_chn0']
[2024-08-29T16:17:53.304+0000] {standard_task_runner.py:105} INFO - Job 30: Subtask tsk_is_file_in_s3_available
[2024-08-29T16:17:53.337+0000] {task_command.py:467} INFO - Running <TaskInstance: zillow_analytics_dag.tsk_is_file_in_s3_available scheduled__2024-08-28T00:00:00+00:00 [running]> on host ip-172-31-11-44.eu-west-3.compute.internal
[2024-08-29T16:17:53.401+0000] {taskinstance.py:3122} INFO - Exporting env vars: AIRFLOW_CTX_DAG_EMAIL='says@master.com' AIRFLOW_CTX_DAG_OWNER='airflow' AIRFLOW_CTX_DAG_ID='zillow_analytics_dag' AIRFLOW_CTX_TASK_ID='tsk_is_file_in_s3_available' AIRFLOW_CTX_EXECUTION_DATE='2024-08-28T00:00:00+00:00' AIRFLOW_CTX_TRY_NUMBER='1' AIRFLOW_CTX_DAG_RUN_ID='scheduled__2024-08-28T00:00:00+00:00'
[2024-08-29T16:17:53.401+0000] {taskinstance.py:731} INFO - ::endgroup::
[2024-08-29T16:17:53.412+0000] {baseoperator.py:405} WARNING - S3KeySensor.execute cannot be called outside TaskInstance!
[2024-08-29T16:17:53.413+0000] {s3.py:118} INFO - Poking for key : s3://cleaned-endtoend-csv-bucket/resonse_data_29082024161729.csv
[2024-08-29T16:17:53.418+0000] {base_aws.py:606} WARNING - Unable to find AWS Connection ID 'cleaned-endtoend-csv-bucket', switching to empty.
[2024-08-29T16:17:53.418+0000] {base_aws.py:180} INFO - No connection ID provided. Fallback on boto3 credential strategy (region_name=None). See: https://boto3.amazonaws.com/v1/documentation/api/latest/guide/configuration.html
[2024-08-29T16:17:53.540+0000] {credentials.py:1075} INFO - Found credentials from IAM Role: ec2-severalaccess-021549
[2024-08-29T16:17:58.773+0000] {s3.py:118} INFO - Poking for key : s3://cleaned-endtoend-csv-bucket/resonse_data_29082024161729.csv
[2024-08-29T16:18:03.785+0000] {s3.py:118} INFO - Poking for key : s3://cleaned-endtoend-csv-bucket/resonse_data_29082024161729.csv
[2024-08-29T16:18:08.798+0000] {s3.py:118} INFO - Poking for key : s3://cleaned-endtoend-csv-bucket/resonse_data_29082024161729.csv
[2024-08-29T16:18:13.811+0000] {s3.py:118} INFO - Poking for key : s3://cleaned-endtoend-csv-bucket/resonse_data_29082024161729.csv
[2024-08-29T16:18:18.820+0000] {s3.py:118} INFO - Poking for key : s3://cleaned-endtoend-csv-bucket/resonse_data_29082024161729.csv
[2024-08-29T16:18:23.830+0000] {s3.py:118} INFO - Poking for key : s3://cleaned-endtoend-csv-bucket/resonse_data_29082024161729.csv
[2024-08-29T16:18:28.843+0000] {s3.py:118} INFO - Poking for key : s3://cleaned-endtoend-csv-bucket/resonse_data_29082024161729.csv
[2024-08-29T16:18:33.853+0000] {s3.py:118} INFO - Poking for key : s3://cleaned-endtoend-csv-bucket/resonse_data_29082024161729.csv
[2024-08-29T16:18:38.865+0000] {s3.py:118} INFO - Poking for key : s3://cleaned-endtoend-csv-bucket/resonse_data_29082024161729.csv
[2024-08-29T16:18:43.875+0000] {s3.py:118} INFO - Poking for key : s3://cleaned-endtoend-csv-bucket/resonse_data_29082024161729.csv
[2024-08-29T16:18:48.885+0000] {s3.py:118} INFO - Poking for key : s3://cleaned-endtoend-csv-bucket/resonse_data_29082024161729.csv
[2024-08-29T16:18:51.443+0000] {local_task_job_runner.py:240} INFO - ::endgroup::
[2024-08-29T16:18:51.451+0000] {process_utils.py:132} INFO - Sending 15 to group 4867. PIDs of all processes in the group: [4867]
[2024-08-29T16:18:51.452+0000] {process_utils.py:87} INFO - Sending the signal 15 to group 4867
[2024-08-29T16:18:51.452+0000] {taskinstance.py:3083} ERROR - Received SIGTERM. Terminating subprocesses.
[2024-08-29T16:18:51.465+0000] {taskinstance.py:3301} ERROR - Task failed with exception
Traceback (most recent call last):
  File "/home/ubuntu/myenv/lib/python3.12/site-packages/airflow/models/taskinstance.py", line 767, in _execute_task
    result = _execute_callable(context=context, **execute_callable_kwargs)
             ^^^^^^^^^^^^^^^^^^^^^^^^^^^^^^^^^^^^^^^^^^^^^^^^^^^^^^^^^^^^^
  File "/home/ubuntu/myenv/lib/python3.12/site-packages/airflow/models/taskinstance.py", line 733, in _execute_callable
    return ExecutionCallableRunner(
           ^^^^^^^^^^^^^^^^^^^^^^^^
  File "/home/ubuntu/myenv/lib/python3.12/site-packages/airflow/utils/operator_helpers.py", line 252, in run
    return self.func(*args, **kwargs)
           ^^^^^^^^^^^^^^^^^^^^^^^^^^
  File "/home/ubuntu/myenv/lib/python3.12/site-packages/airflow/models/baseoperator.py", line 406, in wrapper
    return func(self, *args, **kwargs)
           ^^^^^^^^^^^^^^^^^^^^^^^^^^^
  File "/home/ubuntu/myenv/lib/python3.12/site-packages/airflow/providers/amazon/aws/sensors/s3.py", line 189, in execute
    super().execute(context)
  File "/home/ubuntu/myenv/lib/python3.12/site-packages/airflow/models/baseoperator.py", line 406, in wrapper
    return func(self, *args, **kwargs)
           ^^^^^^^^^^^^^^^^^^^^^^^^^^^
  File "/home/ubuntu/myenv/lib/python3.12/site-packages/airflow/sensors/base.py", line 334, in execute
    time.sleep(self._get_next_poke_interval(started_at, run_duration, poke_count))
  File "/home/ubuntu/myenv/lib/python3.12/site-packages/airflow/models/taskinstance.py", line 3085, in signal_handler
    raise AirflowTaskTerminated("Task received SIGTERM signal")
airflow.exceptions.AirflowTaskTerminated: Task received SIGTERM signal
[2024-08-29T16:18:51.469+0000] {taskinstance.py:1225} INFO - Marking task as UP_FOR_RETRY. dag_id=zillow_analytics_dag, task_id=tsk_is_file_in_s3_available, run_id=scheduled__2024-08-28T00:00:00+00:00, execution_date=20240828T000000, start_date=20240829T161753, end_date=20240829T161851
[2024-08-29T16:18:51.485+0000] {taskinstance.py:340} INFO - ::group::Post task execution logs
[2024-08-29T16:18:51.506+0000] {process_utils.py:80} INFO - Process psutil.Process(pid=4867, status='terminated', exitcode=2, started='16:17:52') (4867) terminated with exit code 2
