[2024-08-29T18:32:40.163+0000] {local_task_job_runner.py:123} INFO - ::group::Pre task execution logs
[2024-08-29T18:32:40.176+0000] {taskinstance.py:2603} INFO - Dependencies all met for dep_context=non-requeueable deps ti=<TaskInstance: zillow_analytics_dag.tsk_transfer_s3_to_redshift manual__2024-08-29T18:29:46.939794+00:00 [queued]>
[2024-08-29T18:32:40.183+0000] {taskinstance.py:2603} INFO - Dependencies all met for dep_context=requeueable deps ti=<TaskInstance: zillow_analytics_dag.tsk_transfer_s3_to_redshift manual__2024-08-29T18:29:46.939794+00:00 [queued]>
[2024-08-29T18:32:40.183+0000] {taskinstance.py:2856} INFO - Starting attempt 2 of 3
[2024-08-29T18:32:40.200+0000] {taskinstance.py:2879} INFO - Executing <Task(S3ToRedshiftOperator): tsk_transfer_s3_to_redshift> on 2024-08-29 18:29:46.939794+00:00
[2024-08-29T18:32:40.204+0000] {standard_task_runner.py:72} INFO - Started process 51911 to run task
[2024-08-29T18:32:40.207+0000] {standard_task_runner.py:104} INFO - Running: ['airflow', 'tasks', 'run', 'zillow_analytics_dag', 'tsk_transfer_s3_to_redshift', 'manual__2024-08-29T18:29:46.939794+00:00', '--job-id', '99', '--raw', '--subdir', 'DAGS_FOLDER/zillow_analytics.py', '--cfg-path', '/tmp/tmpresft248']
[2024-08-29T18:32:40.208+0000] {standard_task_runner.py:105} INFO - Job 99: Subtask tsk_transfer_s3_to_redshift
[2024-08-29T18:32:40.242+0000] {task_command.py:467} INFO - Running <TaskInstance: zillow_analytics_dag.tsk_transfer_s3_to_redshift manual__2024-08-29T18:29:46.939794+00:00 [running]> on host ip-172-31-11-44.eu-west-3.compute.internal
[2024-08-29T18:32:40.308+0000] {taskinstance.py:3122} INFO - Exporting env vars: AIRFLOW_CTX_DAG_EMAIL='says@master.com' AIRFLOW_CTX_DAG_OWNER='airflow' AIRFLOW_CTX_DAG_ID='zillow_analytics_dag' AIRFLOW_CTX_TASK_ID='tsk_transfer_s3_to_redshift' AIRFLOW_CTX_EXECUTION_DATE='2024-08-29T18:29:46.939794+00:00' AIRFLOW_CTX_TRY_NUMBER='2' AIRFLOW_CTX_DAG_RUN_ID='manual__2024-08-29T18:29:46.939794+00:00'
[2024-08-29T18:32:40.308+0000] {taskinstance.py:731} INFO - ::endgroup::
[2024-08-29T18:32:40.323+0000] {base.py:84} INFO - Retrieving connection 'aws_s3_conn'
[2024-08-29T18:32:40.325+0000] {base.py:84} INFO - Retrieving connection 'aws_s3_conn'
[2024-08-29T18:32:40.326+0000] {connection_wrapper.py:388} INFO - AWS Connection (conn_id='aws_s3_conn', conn_type='aws') credentials retrieved from login and password.
[2024-08-29T18:32:40.335+0000] {s3_to_redshift.py:194} INFO - Executing COPY command...
[2024-08-29T18:32:40.337+0000] {base.py:84} INFO - Retrieving connection 'conn_id_redshift'
[2024-08-29T18:34:49.855+0000] {local_task_job_runner.py:240} INFO - ::endgroup::
[2024-08-29T18:34:49.860+0000] {process_utils.py:132} INFO - Sending 15 to group 51911. PIDs of all processes in the group: [51911]
[2024-08-29T18:34:49.860+0000] {process_utils.py:87} INFO - Sending the signal 15 to group 51911
[2024-08-29T18:34:49.860+0000] {taskinstance.py:3083} ERROR - Received SIGTERM. Terminating subprocesses.
[2024-08-29T18:34:49.875+0000] {taskinstance.py:3301} ERROR - Task failed with exception
Traceback (most recent call last):
  File "/home/ubuntu/myenv/lib/python3.12/site-packages/airflow/models/taskinstance.py", line 767, in _execute_task
    result = _execute_callable(context=context, **execute_callable_kwargs)
             ^^^^^^^^^^^^^^^^^^^^^^^^^^^^^^^^^^^^^^^^^^^^^^^^^^^^^^^^^^^^^
  File "/home/ubuntu/myenv/lib/python3.12/site-packages/airflow/models/taskinstance.py", line 733, in _execute_callable
    return ExecutionCallableRunner(
           ^^^^^^^^^^^^^^^^^^^^^^^^
  File "/home/ubuntu/myenv/lib/python3.12/site-packages/airflow/utils/operator_helpers.py", line 252, in run
    return self.func(*args, **kwargs)
           ^^^^^^^^^^^^^^^^^^^^^^^^^^
  File "/home/ubuntu/myenv/lib/python3.12/site-packages/airflow/models/baseoperator.py", line 406, in wrapper
    return func(self, *args, **kwargs)
           ^^^^^^^^^^^^^^^^^^^^^^^^^^^
  File "/home/ubuntu/myenv/lib/python3.12/site-packages/airflow/providers/amazon/aws/transfers/s3_to_redshift.py", line 198, in execute
    redshift_hook.run(sql, autocommit=self.autocommit)
  File "/home/ubuntu/myenv/lib/python3.12/site-packages/airflow/providers/common/sql/hooks/sql.py", line 452, in run
    with self._create_autocommit_connection(autocommit) as conn:
  File "/usr/lib/python3.12/contextlib.py", line 137, in __enter__
    return next(self.gen)
           ^^^^^^^^^^^^^^
  File "/home/ubuntu/myenv/lib/python3.12/site-packages/airflow/providers/common/sql/hooks/sql.py", line 574, in _create_autocommit_connection
    with closing(self.get_conn()) as conn:
                 ^^^^^^^^^^^^^^^
  File "/home/ubuntu/myenv/lib/python3.12/site-packages/airflow/providers/amazon/aws/hooks/redshift_sql.py", line 208, in get_conn
    return redshift_connector.connect(**conn_kwargs)
           ^^^^^^^^^^^^^^^^^^^^^^^^^^^^^^^^^^^^^^^^^
  File "/home/ubuntu/myenv/lib/python3.12/site-packages/redshift_connector/__init__.py", line 394, in connect
    return Connection(
           ^^^^^^^^^^^
  File "/home/ubuntu/myenv/lib/python3.12/site-packages/redshift_connector/core.py", line 634, in __init__
    self._usock.connect(hostport)
  File "/home/ubuntu/myenv/lib/python3.12/site-packages/airflow/models/taskinstance.py", line 3085, in signal_handler
    raise AirflowTaskTerminated("Task received SIGTERM signal")
airflow.exceptions.AirflowTaskTerminated: Task received SIGTERM signal
[2024-08-29T18:34:49.881+0000] {taskinstance.py:1225} INFO - Marking task as UP_FOR_RETRY. dag_id=zillow_analytics_dag, task_id=tsk_transfer_s3_to_redshift, run_id=manual__2024-08-29T18:29:46.939794+00:00, execution_date=20240829T182946, start_date=20240829T183240, end_date=20240829T183449
[2024-08-29T18:34:49.896+0000] {taskinstance.py:340} INFO - ::group::Post task execution logs
[2024-08-29T18:34:49.914+0000] {process_utils.py:80} INFO - Process psutil.Process(pid=51911, status='terminated', exitcode=2, started='18:32:39') (51911) terminated with exit code 2
[2024-08-29T18:34:53.736+0000] {local_task_job_runner.py:123} INFO - ::group::Pre task execution logs
[2024-08-29T18:34:53.742+0000] {taskinstance.py:2593} INFO - Dependencies not met for <TaskInstance: zillow_analytics_dag.tsk_transfer_s3_to_redshift manual__2024-08-29T18:29:46.939794+00:00 [up_for_retry]>, dependency 'Not In Retry Period' FAILED: Task is not ready for retry yet but will be retried automatically. Current date is 2024-08-29T18:34:53.742533+00:00 and task will be retried at 2024-08-29T18:35:04.880910+00:00.
[2024-08-29T18:34:53.751+0000] {local_task_job_runner.py:166} INFO - Task is not able to be run
